{"links": {"self": {"href": "data/repositories/osrf/release-tools/pullrequests/784/comments/96483725.json"}, "html": {"href": "#!/osrf/release-tools/pull-requests/784/_/diff#comment-96483725"}}, "parent": {"id": 96481354, "links": {"self": {"href": "data/repositories/osrf/release-tools/pullrequests/784/comments/96481354.json"}, "html": {"href": "#!/osrf/release-tools/pull-requests/784/_/diff#comment-96481354"}}}, "deleted": false, "pullrequest": {"type": "pullrequest", "id": 784, "links": {"self": {"href": "data/repositories/osrf/release-tools/pullrequests/784.json"}, "html": {"href": "#!/osrf/release-tools/pull-requests/784"}}, "title": "Return custom errors from problems in hg calls during release.py runs"}, "content": {"raw": "do you have an example of a git repo for which the release.py script is used? I'm just curious why we have it", "markup": "markdown", "html": "<p>do you have an example of a git repo for which the release.py script is used? I'm just curious why we have it</p>", "type": "rendered"}, "created_on": "2019-03-26T22:34:29.647401+00:00", "user": {"display_name": "Steve Peters", "uuid": "{2ccfed09-18b8-4921-8d58-15ef01092802}", "links": {"self": {"href": "https://api.bitbucket.org/2.0/users/%7B2ccfed09-18b8-4921-8d58-15ef01092802%7D"}, "html": {"href": "https://bitbucket.org/%7B2ccfed09-18b8-4921-8d58-15ef01092802%7D/"}, "avatar": {"href": "data/secure.gravatar.com/avatar/1fb4816dad9e68337d3096f750951f6cd=httpsavatar-management--avatars.us-west-2.prod.public.atl-paas.netinitialsSP-1.png"}}, "nickname": "Steven Peters", "type": "user", "account_id": "557058:5de38267-b118-494c-aa76-4fab35448816"}, "updated_on": "2019-03-26T22:34:29.654923+00:00", "type": "pullrequest_comment", "id": 96483725}